Workbook

Sheet sequential
A1: SEQUENTIAL
A2: Matrix | B2: Metric | C2: Test 1 | D2: Test 2 | E2: Test 3 | F2: Test 4 | G2: Test 5 | H2: Test 6 | I2: Test 7 | J2: Test 8 | K2: Test 9 | L2: Test 10 | M2: Average | N2: Outlier | O2: 90th perc
A3: 1_little.mtx | B3: CPU [ms] | C3: 220 | D3: 210 | E3: 230 | F3: 220 | G3: 200 | H3: 230 | I3: 140 | J3: 240 | K3: 410 | L3: 270 | M3: =AVERAGE(C3:L3) -> 237 | N3: =MAX(C3:L3) -> 410 | O3: =_xlfn.PERCENTILE.INC(C3:L3, 0.9) -> 284
B4: REAL [ms] | C4: 221.704 | D4: 223.517 | E4: 221.68 | F4: 222.959 | G4: 205.415 | H4: 225.229 | I4: 136.005 | J4: 248.649 | K4: 420.568 | L4: 267.483 | M4: =AVERAGE(C4:L4) -> 239.3209 | N4: =MAX(C4:L4) -> 420.568 | O4: =_xlfn.PERCENTILE.INC(C4:L4, 0.9) -> 282.7915
A5: 2_small.mtx | B5: CPU [ms] | C5: 330 | D5: 330 | E5: 380 | F5: 330 | G5: 370 | H5: 820 | I5: 270 | J5: 400 | K5: 880 | L5: 560 | M5: =AVERAGE(C5:L5) -> 467 | N5: =MAX(C5:L5) -> 880 | O5: =_xlfn.PERCENTILE.INC(C5:L5, 0.9) -> 826
B6: REAL [ms] | C6: 331.161 | D6: 331.025 | E6: 375.384 | F6: 330.003 | G6: 362.534 | H6: 822.173 | I6: 262.019 | J6: 392.524 | K6: 875.947 | L6: 575.836 | M6: =AVERAGE(C6:L6) -> 465.8606 | N6: =MAX(C6:L6) -> 875.947 | O6: =_xlfn.PERCENTILE.INC(C6:L6, 0.9) -> 827.5504
A7: 3_medium.mtx | B7: CPU [ms] | C7: 690 | D7: 720 | E7: 710 | F7: 730 | G7: 630 | H7: 1040 | I7: 1450 | J7: 1060 | K7: 1130 | L7: 1110 | M7: =AVERAGE(C7:L7) -> 927 | N7: =MAX(C7:L7) -> 1450 | O7: =_xlfn.PERCENTILE.INC(C7:L7, 0.9) -> 1162
B8: REAL [ms] | C8: 699.056 | D8: 715.341 | E8: 714.033 | F8: 722.883 | G8: 633.285 | H8: 1045.82 | I8: 1461.3 | J8: 1069.67 | K8: 1142.23 | L8: 1116.22 | M8: =AVERAGE(C8:L8) -> 931.9838 | N8: =MAX(C8:L8) -> 1461.3 | O8: =_xlfn.PERCENTILE.INC(C8:L8, 0.9) -> 1174.137
A9: 4_big.mtx | B9: CPU [ms] | C9: 1230 | D9: 1180 | E9: 1210 | F9: 1210 | G9: 1190 | H9: 1150 | I9: 1410 | J9: 3120 | K9: 2320 | L9: 1690 | M9: =AVERAGE(C9:L9) -> 1571 | N9: =MAX(C9:L9) -> 3120 | O9: =_xlfn.PERCENTILE.INC(C9:L9, 0.9) -> 2400
B10: REAL [ms] | C10: 1233.12 | D10: 1183.09 | E10: 1211.16 | F10: 1203.01 | G10: 1197.86 | H10: 1152.22 | I10: 1416.55 | J10: 3124.88 | K10: 2319.6 | L10: 1688.96 | M10: =AVERAGE(C10:L10) -> 1573.045 | N10: =MAX(C10:L10) -> 3124.88 | O10: =_xlfn.PERCENTILE.INC(C10:L10, 0.9) -> 2400.128
A11: 5_huge.mtx | B11: CPU [ms] | C11: 2390 | D11: 2350 | E11: 2380 | F11: 2250 | G11: 2460 | H11: 4410 | I11: 3590 | J11: 2490 | K11: 3660 | L11: 3560 | M11: =AVERAGE(C11:L11) -> 2954 | N11: =MAX(C11:L11) -> 4410 | O11: =_xlfn.PERCENTILE.INC(C11:L11, 0.9) -> 3735
B12: REAL [ms] | C12: 2386.72 | D12: 2364.34 | E12: 2381.91 | F12: 2249.73 | G12: 2470.02 | H12: 4418.93 | I12: 3601.23 | J12: 2495.31 | K12: 3667.92 | L12: 3567.6 | M12: =AVERAGE(C12:L12) -> 2960.371 | N12: =MAX(C12:L12) -> 4418.93 | O12: =_xlfn.PERCENTILE.INC(C12:L12, 0.9) -> 3743.021

Sheet parallel_no_simd
A1: PARALLEL NO SIMD STATIC - 4 THREADS
A2: Matrix | B2: Metric | C2: Test 1 | D2: Test 2 | E2: Test 3 | F2: Test 4 | G2: Test 5 | H2: Test 6 | I2: Test 7 | J2: Test 8 | K2: Test 9 | L2: Test 10 | M2: Average | N2: Outlier | O2: 90th perc
A3: 1_little.mtx | B3: CPU [ms] | C3: 530 | D3: 350 | E3: 540 | F3: 360 | G3: 280 | H3: 290 | I3: 290 | J3: 350 | K3: 660 | L3: 300 | M3: =AVERAGE(C3:L3) -> 395 | N3: =MAX(C3:L3) -> 660 | O3: =_xlfn.PERCENTILE.INC(C3:L3, 0.9) -> 552
B4: REAL [ms] | C4: 552.043 | D4: 347.344 | E4: 531.363 | F4: 369.633 | G4: 295.791 | H4: 277.022 | I4: 283.868 | J4: 707.167 | K4: 1010.99 | L4: 607.186 | M4: =AVERAGE(C4:L4) -> 498.2407 | N4: =MAX(C4:L4) -> 1010.99 | O4: =_xlfn.PERCENTILE.INC(C4:L4, 0.9) -> 737.5493
A5: 2_small.mtx | B5: CPU [ms] | C5: 850 | D5: 790 | E5: 540 | F5: 490 | G5: 560 | H5: 510 | I5: 530 | J5: 560 | K5: 470 | L5: 490 | M5: =AVERAGE(C5:L5) -> 579 | N5: =MAX(C5:L5) -> 850 | O5: =_xlfn.PERCENTILE.INC(C5:L5, 0.9) -> 796
B6: REAL [ms] | C6: 1487.8 | D6: 1615.1 | E6: 1025.23 | F6: 492.981 | G6: 560.516 | H6: 729.551 | I6: 766.37 | J6: 632.833 | K6: 759.704 | L6: 936.146 | M6: =AVERAGE(C6:L6) -> 900.6231 | N6: =MAX(C6:L6) -> 1615.1 | O6: =_xlfn.PERCENTILE.INC(C6:L6, 0.9) -> 1500.53
A7: 3_medium.mtx | B7: CPU [ms] | C7: 1450 | D7: 1100 | E7: 2500 | F7: 1560 | G7: 1000 | H7: 840 | I7: 930 | J7: 840 | K7: 1120 | L7: 1000 | M7: =AVERAGE(C7:L7) -> 1234 | N7: =MAX(C7:L7) -> 2500 | O7: =_xlfn.PERCENTILE.INC(C7:L7, 0.9) -> 1654
B8: REAL [ms] | C8: 1587.18 | D8: 1402.95 | E8: 5173.04 | F8: 2817.57 | G8: 989.265 | H8: 930.694 | I8: 1236.79 | J8: 863.19 | K8: 1562.23 | L8: 1046.01 | M8: =AVERAGE(C8:L8) -> 1760.8919 | N8: =MAX(C8:L8) -> 5173.04 | O8: =_xlfn.PERCENTILE.INC(C8:L8, 0.9) -> 3053.117
A9: 4_big.mtx | B9: CPU [ms] | C9: 3130 | D9: 1870 | E9: 2360 | F9: 4170 | G9: 1470 | H9: 1390 | I9: 3150 | J9: 2020 | K9: 2060 | L9: 1770 | M9: =AVERAGE(C9:L9) -> 2339 | N9: =MAX(C9:L9) -> 4170 | O9: =_xlfn.PERCENTILE.INC(C9:L9, 0.9) -> 3252
B10: REAL [ms] | C10: 4814.4 | D10: 2566.82 | E10: 3137.05 | F10: 4900.39 | G10: 1703.35 | H10: 1499.69 | I10: 4351.65 | J10: 2285.4 | K10: 3032.99 | L10: 2459.6 | M10: =AVERAGE(C10:L10) -> 3075.134 | N10: =MAX(C10:L10) -> 4900.39 | O10: =_xlfn.PERCENTILE.INC(C10:L10, 0.9) -> 4822.999
A11: 5_huge.mtx | B11: CPU [ms] | C11: 5490 | D11: 4870 | E11: 7890 | F11: 6620 | G11: 2950 | H11: 3990 | I11: 3360 | J11: 4070 | K11: 3540 | L11: 3450 | M11: =AVERAGE(C11:L11) -> 4623 | N11: =MAX(C11:L11) -> 7890 | O11: =_xlfn.PERCENTILE.INC(C11:L11, 0.9) -> 6747
B12: REAL [ms] | C12: 8060.13 | D12: 6050.85 | E12: 10970.3 | F12: 10151.5 | G12: 5170.02 | H12: 4479.26 | I12: 4572.53 | J12: 4310.49 | K12: 4294.33 | L12: 3794.21 | M12: =AVERAGE(C12:L12) -> 6185.362 | N12: =MAX(C12:L12) -> 10970.3 | O12: =_xlfn.PERCENTILE.INC(C12:L12, 0.9) -> 10233.38
A14: PARALLEL NO SIMD DYNAMIC - 4 THREADS
A15: Matrix | B15: Metric | C15: Test 1 | D15: Test 2 | E15: Test 3 | F15: Test 4 | G15: Test 5 | H15: Test 6 | I15: Test 7 | J15: Test 8 | K15: Test 9 | L15: Test 10 | M15: Average | N15: Outlier | O15: 90th perc
A16: 1_little.mtx | B16: CPU [ms] | C16: 510 | D16: 480 | E16: 410 | F16: 500 | G16: 310 | H16: 310 | I16: 250 | J16: 510 | K16: 470 | L16: 590 | M16: =AVERAGE(C16:L16) -> 434 | N16: =MAX(C16:L16) -> 590 | O16: =_xlfn.PERCENTILE.INC(C16:L16, 0.9) -> 518
B17: REAL [ms] | C17: 524.075 | D17: 898.988 | E17: 414.799 | F17: 519.337 | G17: 307.435 | H17: 312.319 | I17: 251.764 | J17: 624.512 | K17: 823.454 | L17: 933.974 | M17: =AVERAGE(C17:L17) -> 561.0657 | N17: =MAX(C17:L17) -> 933.974 | O17: =_xlfn.PERCENTILE.INC(C17:L17, 0.9) -> 902.4866
A18: 2_small.mtx | B18: CPU [ms] | C18: 800 | D18: 1070 | E18: 780 | F18: 820 | G18: 1030 | H18: 640 | I18: 600 | J18: 1050 | K18: 970 | L18: 1070 | M18: =AVERAGE(C18:L18) -> 883 | N18: =MAX(C18:L18) -> 1070 | O18: =_xlfn.PERCENTILE.INC(C18:L18, 0.9) -> 1070
B19: REAL [ms] | C19: 821.741 | D19: 1141.09 | E19: 968.93 | F19: 1099.13 | G19: 2337.36 | H19: 708.056 | I19: 608.308 | J19: 1157.59 | K19: 987.034 | L19: 1244.5 | M19: =AVERAGE(C19:L19) -> 1107.3739 | N19: =MAX(C19:L19) -> 2337.36 | O19: =_xlfn.PERCENTILE.INC(C19:L19, 0.9) -> 1353.786
A20: 3_medium.mtx | B20: CPU [ms] | C20: 1130 | D20: 1350 | E20: 1330 | F20: 910 | G20: 1810 | H20: 1910 | I20: 1230 | J20: 1680 | K20: 1140 | L20: 2680 | M20: =AVERAGE(C20:L20) -> 1517 | N20: =MAX(C20:L20) -> 2680 | O20: =_xlfn.PERCENTILE.INC(C20:L20, 0.9) -> 1987
B21: REAL [ms] | C21: 1128.09 | D21: 1343.27 | E21: 1341.16 | F21: 918.465 | G21: 3309.69 | H21: 1918.84 | I21: 2515.71 | J21: 1682.46 | K21: 2285.84 | L21: 2700.98 | M21: =AVERAGE(C21:L21) -> 1914.4505 | N21: =MAX(C21:L21) -> 3309.69 | O21: =_xlfn.PERCENTILE.INC(C21:L21, 0.9) -> 2761.851
A22: 4_big.mtx | B22: CPU [ms] | C22: 2910 | D22: 4180 | E22: 2650 | F22: 3220 | G22: 2290 | H22: 3200 | I22: 1660 | J22: 2730 | K22: 2100 | L22: 6270 | M22: =AVERAGE(C22:L22) -> 3121 | N22: =MAX(C22:L22) -> 6270 | O22: =_xlfn.PERCENTILE.INC(C22:L22, 0.9) -> 4389
B23: REAL [ms] | C23: 2923.13 | D23: 4181.91 | E23: 2655.24 | F23: 4171.11 | G23: 2301.96 | H23: 3627.83 | I23: 1663.24 | J23: 2753.89 | K23: 2120.05 | L23: 7584.49 | M23: =AVERAGE(C23:L23) -> 3398.285 | N23: =MAX(C23:L23) -> 7584.49 | O23: =_xlfn.PERCENTILE.INC(C23:L23, 0.9) -> 4522.168
A24: 5_huge.mtx | B24: CPU [ms] | C24: 2720 | D24: 5180 | E24: 5320 | F24: 2680 | G24: 3870 | H24: 2880 | I24: 4920 | J24: 9120 | K24: 3920 | L24: 5510 | M24: =AVERAGE(C24:L24) -> 4612 | N24: =MAX(C24:L24) -> 9120 | O24: =_xlfn.PERCENTILE.INC(C24:L24, 0.9) -> 5871
B25: REAL [ms] | C25: 2722.72 | D25: 10022.7 | E25: 7333.78 | F25: 2686.66 | G25: 3872.89 | H25: 2892 | I25: 5123.9 | J25: 9140.31 | K25: 3935.12 | L25: 8573.51 | M25: =AVERAGE(C25:L25) -> 5630.359 | N25: =MAX(C25:L25) -> 10022.7 | O25: =_xlfn.PERCENTILE.INC(C25:L25, 0.9) -> 9228.549
A27: PARALLEL NO SIMD GUIDED - 4 THREADS
A28: Matrix | B28: Metric | C28: Test 1 | D28: Test 2 | E28: Test 3 | F28: Test 4 | G28: Test 5 | H28: Test 6 | I28: Test 7 | J28: Test 8 | K28: Test 9 | L28: Test 10 | M28: Average | N28: Outlier | O28: 90th perc
A29: 1_little.mtx | B29: CPU [ms] | C29: 390 | D29: 270 | E29: 700 | F29: 320 | G29: 330 | H29: 180 | I29: 480 | J29: 180 | K29: 210 | L29: 270 | M29: =AVERAGE(C29:L29) -> 333 | N29: =MAX(C29:L29) -> 700 | O29: =_xlfn.PERCENTILE.INC(C29:L29, 0.9) -> 502
B30: REAL [ms] | C30: 388.97 | D30: 266.247 | E30: 704.601 | F30: 320.097 | G30: 329.796 | H30: 170.962 | I30: 472.132 | J30: 180.634 | K30: 198.888 | L30: 277.013 | M30: =AVERAGE(C30:L30) -> 330.934 | N30: =MAX(C30:L30) -> 704.601 | O30: =_xlfn.PERCENTILE.INC(C30:L30, 0.9) -> 495.3789
A31: 2_small.mtx | B31: CPU [ms] | C31: 900 | D31: 1070 | E31: 610 | F31: 540 | G31: 920 | H31: 670 | I31: 880 | J31: 980 | K31: 600 | L31: 900 | M31: =AVERAGE(C31:L31) -> 807 | N31: =MAX(C31:L31) -> 1070 | O31: =_xlfn.PERCENTILE.INC(C31:L31, 0.9) -> 989
B32: REAL [ms] | C32: 908.926 | D32: 1069.92 | E32: 611.748 | F32: 553.338 | G32: 921.413 | H32: 679.125 | I32: 884.265 | J32: 971.043 | K32: 594.371 | L32: 902.906 | M32: =AVERAGE(C32:L32) -> 809.7055 | N32: =MAX(C32:L32) -> 1069.92 | O32: =_xlfn.PERCENTILE.INC(C32:L32, 0.9) -> 980.9307
A33: 3_medium.mtx | B33: CPU [ms] | C33: 1960 | D33: 810 | E33: 1670 | F33: 1570 | G33: 1300 | H33: 1190 | I33: 1640 | J33: 1670 | K33: 790 | L33: 1780 | M33: =AVERAGE(C33:L33) -> 1438 | N33: =MAX(C33:L33) -> 1960 | O33: =_xlfn.PERCENTILE.INC(C33:L33, 0.9) -> 1798
B34: REAL [ms] | C34: 1960.23 | D34: 808.807 | E34: 1675.32 | F34: 1572.53 | G34: 1304.17 | H34: 1189.72 | I34: 1652.18 | J34: 1681.93 | K34: 789.96 | L34: 1780.88 | M34: =AVERAGE(C34:L34) -> 1441.5727 | N34: =MAX(C34:L34) -> 1960.23 | O34: =_xlfn.PERCENTILE.INC(C34:L34, 0.9) -> 1798.815
A35: 4_big.mtx | B35: CPU [ms] | C35: 3180 | D35: 1850 | E35: 3670 | F35: 2720 | G35: 2710 | H35: 3680 | I35: 3430 | J35: 3290 | K35: 2660 | L35: 3200 | M35: =AVERAGE(C35:L35) -> 3039 | N35: =MAX(C35:L35) -> 3680 | O35: =_xlfn.PERCENTILE.INC(C35:L35, 0.9) -> 3671
B36: REAL [ms] | C36: 3180.45 | D36: 1853.15 | E36: 3682.4 | F36: 2719.59 | G36: 2719.8 | H36: 3691.07 | I36: 3436.49 | J36: 3286.47 | K36: 2660.35 | L36: 3201.19 | M36: =AVERAGE(C36:L36) -> 3043.096 | N36: =MAX(C36:L36) -> 3691.07 | O36: =_xlfn.PERCENTILE.INC(C36:L36, 0.9) -> 3683.267
A37: 5_huge.mtx | B37: CPU [ms] | C37: 4610 | D37: 6530 | E37: 6570 | F37: 6010 | G37: 5690 | H37: 5760 | I37: 4240 | J37: 3380 | K37: 4350 | L37: 3970 | M37: =AVERAGE(C37:L37) -> 5111 | N37: =MAX(C37:L37) -> 6570 | O37: =_xlfn.PERCENTILE.INC(C37:L37, 0.9) -> 6534
B38: REAL [ms] | C38: 4623.51 | D38: 6546.8 | E38: 6596.93 | F38: 6024.49 | G38: 5711.95 | H38: 5771.58 | I38: 4250.47 | J38: 3387.67 | K38: 4374.52 | L38: 3975.27 | M38: =AVERAGE(C38:L38) -> 5126.319 | N38: =MAX(C38:L38) -> 6596.93 | O38: =_xlfn.PERCENTILE.INC(C38:L38, 0.9) -> 6551.813
A42: PARALLEL NO SIMD STATIC - 8 THREADS
A43: Matrix | B43: Metric | C43: Test 1 | D43: Test 2 | E43: Test 3 | F43: Test 4 | G43: Test 5 | H43: Test 6 | I43: Test 7 | J43: Test 8 | K43: Test 9 | L43: Test 10 | M43: Average | N43: Outlier | O43: 90th perc
A44: 1_little.mtx | B44: CPU [ms] | C44: 160 | D44: 380 | E44: 270 | F44: 210 | G44: 160 | H44: 210 | I44: 150 | J44: 290 | K44: 310 | L44: 320 | M44: =AVERAGE(C44:L44) -> 246 | N44: =MAX(C44:L44) -> 380 | O44: =_xlfn.PERCENTILE.INC(C44:L44, 0.9) -> 326
B45: REAL [ms] | C45: 156.901 | D45: 381.921 | E45: 271.721 | F45: 220.016 | G45: 155.684 | H45: 195.978 | I45: 146.72 | J45: 279.756 | K45: 306.102 | L45: 325.008 | M45: =AVERAGE(C45:L45) -> 243.9807 | N45: =MAX(C45:L45) -> 381.921 | O45: =_xlfn.PERCENTILE.INC(C45:L45, 0.9) -> 330.6993
...

Sheet parallel_simd
A1: PARALLEL SIMD STATIC - 4 THREADS
A2: Matrix | B2: Metric | C2: Test 1 | D2: Test 2 | E2: Test 3 | F2: Test 4 | G2: Test 5 | H2: Test 6 | I2: Test 7 | J2: Test 8 | K2: Test 9 | L2: Test 10 | M2: Average | N2: Outlier | O2: 90th perc
A3: 1_little.mtx | B3: CPU [ms] | C3: 930 | D3: 210 | E3: 510 | F3: 970 | G3: 170 | H3: 160 | I3: 190 | J3: 150 | K3: 420 | L3: 190 | M3: =AVERAGE(C3:L3) -> 390 | N3: =MAX(C3:L3) -> 970 | O3: =_xlfn.PERCENTILE.INC(C3:L3, 0.9) -> 934
B4: REAL [ms] | C4: 937.563 | D4: 205.963 | E4: 547.507 | F4: 1181.8 | G4: 177.079 | H4: 155.01 | I4: 188.008 | J4: 144.597 | K4: 430.664 | L4: 190.981 | M4: =AVERAGE(C4:L4) -> 415.9172 | N4: =MAX(C4:L4) -> 1181.8 | O4: =_xlfn.PERCENTILE.INC(C4:L4, 0.9) -> 961.9867
A5: 2_small.mtx | B5: CPU [ms] | C5: 880 | D5: 1420 | E5: 1380 | F5: 1300 | G5: 840 | H5: 500 | I5: 530 | J5: 470 | K5: 840 | L5: 300 | M5: =AVERAGE(C5:L5) -> 846 | N5: =MAX(C5:L5) -> 1420 | O5: =_xlfn.PERCENTILE.INC(C5:L5, 0.9) -> 1384
B6: REAL [ms] | C6: 878.849 | D6: 1413.21 | E6: 1392.57 | F6: 1307.05 | G6: 849.961 | H6: 998.01 | I6: 531.803 | J6: 519.325 | K6: 970.214 | L6: 299.47 | M6: =AVERAGE(C6:L6) -> 916.0462 | N6: =MAX(C6:L6) -> 1413.21 | O6: =_xlfn.PERCENTILE.INC(C6:L6, 0.9) -> 1394.634
A7: 3_medium.mtx | B7: CPU [ms] | C7: 2140 | D7: 3130 | E7: 1230 | F7: 1010 | G7: 1660 | H7: 1260 | I7: 910 | J7: 960 | K7: 1340 | L7: 720 | M7: =AVERAGE(C7:L7) -> 1436 | N7: =MAX(C7:L7) -> 3130 | O7: =_xlfn.PERCENTILE.INC(C7:L7, 0.9) -> 2239
B8: REAL [ms] | C8: 2136.02 | D8: 3354.68 | E8: 1224.65 | F8: 1012.4 | G8: 1705.46 | H8: 1269.55 | I8: 921.689 | J8: 963.174 | K8: 1346.82 | L8: 723.579 | M8: =AVERAGE(C8:L8) -> 1465.8022 | N8: =MAX(C8:L8) -> 3354.68 | O8: =_xlfn.PERCENTILE.INC(C8:L8, 0.9) -> 2257.886
A9: 4_big.mtx | B9: CPU [ms] | C9: 5620 | D9: 3340 | E9: 3020 | F9: 1550 | G9: 2330 | H9: 2180 | I9: 1460 | J9: 940 | K9: 1870 | L9: 1020 | M9: =AVERAGE(C9:L9) -> 2333 | N9: =MAX(C9:L9) -> 5620 | O9: =_xlfn.PERCENTILE.INC(C9:L9, 0.9) -> 3568
B10: REAL [ms] | C10: 5633.82 | D10: 3358.96 | E10: 4375.73 | F10: 1555.09 | G10: 2335.15 | H10: 2187.8 | I10: 1457.2 | J10: 948.076 | K10: 1870.21 | L10: 1018.57 | M10: =AVERAGE(C10:L10) -> 2474.0606 | N10: =MAX(C10:L10) -> 5633.82 | O10: =_xlfn.PERCENTILE.INC(C10:L10, 0.9) -> 4501.539
A11: 5_huge.mtx | B11: CPU [ms] | C11: 8450 | D11: 8140 | E11: 7360 | F11: 4310 | G11: 4030 | H11: 1840 | I11: 1730 | J11: 2730 | K11: 2890 | L11: 1790 | M11: =AVERAGE(C11:L11) -> 4327 | N11: =MAX(C11:L11) -> 8450 | O11: =_xlfn.PERCENTILE.INC(C11:L11, 0.9) -> 8171
B12: REAL [ms] | C12: 8474.37 | D12: 10775.9 | E12: 8328.48 | F12: 4310.44 | G12: 4039.83 | H12: 1851.2 | I12: 1729.8 | J12: 2924.02 | K12: 2893.15 | L12: 1794.41 | M12: =AVERAGE(C12:L12) -> 4712.16 | N12: =MAX(C12:L12) -> 10775.9 | O12: =_xlfn.PERCENTILE.INC(C12:L12, 0.9) -> 8704.523
A14: PARALLEL SIMD DYNAMIC - 4 THREADS
A15: Matrix | B15: Metric | C15: Test 1 | D15: Test 2 | E15: Test 3 | F15: Test 4 | G15: Test 5 | H15: Test 6 | I15: Test 7 | J15: Test 8 | K15: Test 9 | L15: Test 10 | M15: Average | N15: Outlier | O15: 90th perc
A16: 1_little.mtx | B16: CPU [ms] | C16: 510 | D16: 270 | E16: 480 | F16: 220 | G16: 630 | H16: 370 | I16: 210 | J16: 300 | K16: 480 | L16: 260 | M16: =AVERAGE(C16:L16) -> 373 | N16: =MAX(C16:L16) -> 630 | O16: =_xlfn.PERCENTILE.INC(C16:L16, 0.9) -> 522
B17: REAL [ms] | C17: 518.568 | D17: 272.055 | E17: 486.399 | F17: 222.402 | G17: 621.928 | H17: 363.303 | I17: 213.177 | J17: 304.409 | K17: 481.876 | L17: 255.497 | M17: =AVERAGE(C17:L17) -> 373.9614 | N17: =MAX(C17:L17) -> 621.928 | O17: =_xlfn.PERCENTILE.INC(C17:L17, 0.9) -> 528.904
A18: 2_small.mtx | B18: CPU [ms] | C18: 600 | D18: 480 | E18: 610 | F18: 440 | G18: 680 | H18: 410 | I18: 570 | J18: 610 | K18: 630 | L18: 830 | M18: =AVERAGE(C18:L18) -> 586 | N18: =MAX(C18:L18) -> 830 | O18: =_xlfn.PERCENTILE.INC(C18:L18, 0.9) -> 695
B19: REAL [ms] | C19: 603.845 | D19: 478.017 | E19: 609.482 | F19: 442.278 | G19: 683.383 | H19: 407.811 | I19: 564.622 | J19: 618.206 | K19: 637.478 | L19: 832.042 | M19: =AVERAGE(C19:L19) -> 587.7164 | N19: =MAX(C19:L19) -> 832.042 | O19: =_xlfn.PERCENTILE.INC(C19:L19, 0.9) -> 698.2489
A20: 3_medium.mtx | B20: CPU [ms] | C20: 1810 | D20: 1810 | E20: 1090 | F20: 1800 | G20: 1100 | H20: 1130 | I20: 1770 | J20: 1190 | K20: 880 | L20: 940 | M20: =AVERAGE(C20:L20) -> 1352 | N20: =MAX(C20:L20) -> 1810 | O20: =_xlfn.PERCENTILE.INC(C20:L20, 0.9) -> 1810
B21: REAL [ms] | C21: 1819.78 | D21: 1810.89 | E21: 1100.33 | F21: 1800.85 | G21: 1097.97 | H21: 1130.46 | I21: 1777.17 | J21: 1193.51 | K21: 884.355 | L21: 943.76 | M21: =AVERAGE(C21:L21) -> 1355.9075 | N21: =MAX(C21:L21) -> 1819.78 | O21: =_xlfn.PERCENTILE.INC(C21:L21, 0.9) -> 1811.779
A22: 4_big.mtx | B22: CPU [ms] | C22: 3280 | D22: 2050 | E22: 3510 | F22: 1880 | G22: 4610 | H22: 3810 | I22: 2930 | J22: 3710 | K22: 1960 | L22: 2900 | M22: =AVERAGE(C22:L22) -> 3064 | N22: =MAX(C22:L22) -> 4610 | O22: =_xlfn.PERCENTILE.INC(C22:L22, 0.9) -> 3890
B23: REAL [ms] | C23: 3281.01 | D23: 2051.21 | E23: 3522.05 | F23: 1888.22 | G23: 4618.94 | H23: 3825.6 | I23: 2933.65 | J23: 3719.92 | K23: 1965.31 | L23: 2898.65 | M23: =AVERAGE(C23:L23) -> 3070.456 | N23: =MAX(C23:L23) -> 4618.94 | O23: =_xlfn.PERCENTILE.INC(C23:L23, 0.9) -> 3904.934
A24: 5_huge.mtx | B24: CPU [ms] | C24: 7140 | D24: 5740 | E24: 5740 | F24: 5890 | G24: 5140 | H24: 4390 | I24: 4670 | J24: 6540 | K24: 7200 | L24: 5580 | M24: =AVERAGE(C24:L24) -> 5803 | N24: =MAX(C24:L24) -> 7200 | O24: =_xlfn.PERCENTILE.INC(C24:L24, 0.9) -> 7146
B25: REAL [ms] | C25: 7146.63 | D25: 5756.65 | E25: 5751.46 | F25: 5903.05 | G25: 5160.98 | H25: 4404.44 | I25: 4676.74 | J25: 6558.54 | K25: 7216.65 | L25: 5594.42 | M25: =AVERAGE(C25:L25) -> 5816.956 | N25: =MAX(C25:L25) -> 7216.65 | O25: =_xlfn.PERCENTILE.INC(C25:L25, 0.9) -> 7153.632
A27: PARALLEL SIMD GUIDED - 4 THREADS
A28: Matrix | B28: Metric | C28: Test 1 | D28: Test 2 | E28: Test 3 | F28: Test 4 | G28: Test 5 | H28: Test 6 | I28: Test 7 | J28: Test 8 | K28: Test 9 | L28: Test 10 | M28: Average | N28: Outlier | O28: 90th perc
A29: 1_little.mtx | B29: CPU [ms] | C29: 180 | D29: 140 | E29: 120 | F29: 130 | G29: 140 | H29: 130 | I29: 150 | J29: 130 | K29: 170 | L29: 140 | M29: =AVERAGE(C29:L29) -> 143 | N29: =MAX(C29:L29) -> 180 | O29: =_xlfn.PERCENTILE.INC(C29:L29, 0.9) -> 171
B30: REAL [ms] | C30: 178.551 | D30: 143.17 | E30: 129.035 | F30: 130.648 | G30: 132.276 | H30: 131.796 | I30: 156.407 | J30: 130.524 | K30: 168.628 | L30: 136.167 | M30: =AVERAGE(C30:L30) -> 143.7202 | N30: =MAX(C30:L30) -> 178.551 | O30: =_xlfn.PERCENTILE.INC(C30:L30, 0.9) -> 169.6203
A31: 2_small.mtx | B31: CPU [ms] | C31: 390 | D31: 360 | E31: 340 | F31: 240 | G31: 260 | H31: 280 | I31: 340 | J31: 240 | K31: 310 | L31: 250 | M31: =AVERAGE(C31:L31) -> 301 | N31: =MAX(C31:L31) -> 390 | O31: =_xlfn.PERCENTILE.INC(C31:L31, 0.9) -> 363
B32: REAL [ms] | C32: 391.465 | D32: 364.945 | E32: 353.637 | F32: 246.991 | G32: 258.855 | H32: 282.803 | I32: 337.727 | J32: 246.543 | K32: 308.12 | L32: 249.823 | M32: =AVERAGE(C32:L32) -> 304.0909 | N32: =MAX(C32:L32) -> 391.465 | O32: =_xlfn.PERCENTILE.INC(C32:L32, 0.9) -> 367.597
A33: 3_medium.mtx | B33: CPU [ms] | C33: 600 | D33: 690 | E33: 600 | F33: 660 | G33: 510 | H33: 580 | I33: 580 | J33: 480 | K33: 460 | L33: 450 | M33: =AVERAGE(C33:L33) -> 561 | N33: =MAX(C33:L33) -> 690 | O33: =_xlfn.PERCENTILE.INC(C33:L33, 0.9) -> 663
B34: REAL [ms] | C34: 598.443 | D34: 693.675 | E34: 612.551 | F34: 667.219 | G34: 505.014 | H34: 587.689 | I34: 581.169 | J34: 475.444 | K34: 461.366 | L34: 461.998 | M34: =AVERAGE(C34:L34) -> 564.4568 | N34: =MAX(C34:L34) -> 693.675 | O34: =_xlfn.PERCENTILE.INC(C34:L34, 0.9) -> 669.8646
A35: 4_big.mtx | B35: CPU [ms] | C35: 930 | D35: 1300 | E35: 1180 | F35: 1270 | G35: 1020 | H35: 850 | I35: 1180 | J35: 880 | K35: 1310 | L35: 1250 | M35: =AVERAGE(C35:L35) -> 1117 | N35: =MAX(C35:L35) -> 1310 | O35: =_xlfn.PERCENTILE.INC(C35:L35, 0.9) -> 1301
B36: REAL [ms] | C36: 940.919 | D36: 1290.36 | E36: 1181.61 | F36: 1277.62 | G36: 1031.18 | H36: 851.646 | I36: 1168.51 | J36: 873.874 | K36: 1319.04 | L36: 1258.53 | M36: =AVERAGE(C36:L36) -> 1119.3289 | N36: =MAX(C36:L36) -> 1319.04 | O36: =_xlfn.PERCENTILE.INC(C36:L36, 0.9) -> 1293.228
A37: 5_huge.mtx | B37: CPU [ms] | C37: 1790 | D37: 1730 | E37: 2000 | F37: 2250 | G37: 1940 | H37: 2300 | I37: 2120 | J37: 1530 | K37: 2220 | L37: 2040 | M37: =AVERAGE(C37:L37) -> 1992 | N37: =MAX(C37:L37) -> 2300 | O37: =_xlfn.PERCENTILE.INC(C37:L37, 0.9) -> 2255
B38: REAL [ms] | C38: 1798.64 | D38: 1732.47 | E38: 2002.85 | F38: 2254.32 | G38: 1951.2 | H38: 2303.81 | I38: 2119.08 | J38: 1531.7 | K38: 2223.42 | L38: 2049.46 | M38: =AVERAGE(C38:L38) -> 1996.695 | N38: =MAX(C38:L38) -> 2303.81 | O38: =_xlfn.PERCENTILE.INC(C38:L38, 0.9) -> 2259.269
A42: PARALLEL SIMD STATIC - 8 THREADS
A43: Matrix | B43: Metric | C43: Test 1 | D43: Test 2 | E43: Test 3 | F43: Test 4 | G43: Test 5 | H43: Test 6 | I43: Test 7 | J43: Test 8 | K43: Test 9 | L43: Test 10 | M43: Average | N43: Outlier | O43: 90th perc
A44: 1_little.mtx | B44: CPU [ms] | C44: 170 | D44: 210 | E44: 170 | F44: 210 | G44: 150 | H44: 260 | I44: 220 | J44: 210 | K44: 140 | L44: 210 | M44: =AVERAGE(C44:L44) -> 195 | N44: =MAX(C44:L44) -> 260 | O44: =_xlfn.PERCENTILE.INC(C44:L44, 0.9) -> 224
B45: REAL [ms] | C45: 167.584 | D45: 215.659 | E45: 170.373 | F45: 209.661 | G45: 145.062 | H45: 509.657 | I45: 214.52 | J45: 223.478 | K45: 147.001 | L45: 397.376 | M45: =AVERAGE(C45:L45) -> 240.0371 | N45: =MAX(C45:L45) -> 509.657 | O45: =_xlfn.PERCENTILE.INC(C45:L45, 0.9) -> 408.6041
...

Sheet final_results
A1: ABSOLUTE COMPARISON
A2: Matrix | B2: Metric | C2: Sequential | D2: Parallel no simd | E2: Parallel simd | F2: Best | G2: Speed-Up
A3: 1_little.mtx | B3: CPU [ms] | C3: =sequential!O3 -> 284 | D3: =parallel_no_simd!F249 -> 130 | E3: =parallel_simd!F293 -> 131 | F3: =MIN(C3:E3) -> 130 | G3: =C3/D3 -> 2.1846154
B4: REAL [ms] | C4: =sequential!O4 -> 282.7915 | D4: =parallel_no_simd!F250 -> 124.7916 | E4: =parallel_simd!F294 -> 124.4472 | F4: =MIN(C4:E4) -> 124.4472 | G4: =C4/E4 -> 2.2723814
A5: 2_small.mtx | B5: CPU [ms] | C5: =sequential!O5 -> 826 | D5: =parallel_no_simd!F251 -> 240 | E5: =parallel_simd!F295 -> 240 | F5: =MIN(C5:E5) -> 240 | G5: =C5/D5 -> 3.4416667
B6: REAL [ms] | C6: =sequential!O6 -> 827.5504 | D6: =parallel_no_simd!F252 -> 234.7095 | E6: =parallel_simd!F296 -> 235.9917 | F6: =MIN(C6:E6) -> 234.7095 | G6: =C6/D6 -> 3.5258496
A7: 3_medium.mtx | B7: CPU [ms] | C7: =sequential!O7 -> 1162 | D7: =parallel_no_simd!F253 -> 450 | E7: =parallel_simd!F297 -> 450 | F7: =MIN(C7:E7) -> 450 | G7: =C7/E7 -> 2.5822222
B8: REAL [ms] | C8: =sequential!O8 -> 1174.137 | D8: =parallel_no_simd!F254 -> 450.208 | E8: =parallel_simd!F298 -> 441.1603 | F8: =MIN(C8:E8) -> 441.1603 | G8: =C8/E8 -> 2.6614748
A9: 4_big.mtx | B9: CPU [ms] | C9: =sequential!O9 -> 2400 | D9: =parallel_no_simd!F255 -> 830 | E9: =parallel_simd!F299 -> 889 | F9: =MIN(C9:E9) -> 830 | G9: =C9/D9 -> 2.8915663
B10: REAL [ms] | C10: =sequential!O10 -> 2400.128 | D10: =parallel_no_simd!F256 -> 829.8356 | E10: =parallel_simd!F300 -> 883.2338 | F10: =MIN(C10:E10) -> 829.8356 | G10: =C10/D10 -> 2.8922934
A11: 5_huge.mtx | B11: CPU [ms] | C11: =sequential!O11 -> 3735 | D11: =parallel_no_simd!F257 -> 2248 | E11: =parallel_simd!F301 -> 1742 | F11: =MIN(C11:E11) -> 1742 | G11: =C11/E11 -> 2.1440873
B12: REAL [ms] | C12: =sequential!O12 -> 3743.021 | D12: =parallel_no_simd!F258 -> 2262.799 | E12: =parallel_simd!F302 -> 1746.933 | F12: =MIN(C12:E12) -> 1746.933 | G12: =C12/E12 -> 2.1426242
